Traceback (most recent call last):
  File "/opt/anaconda3/lib/python3.11/site-packages/jupyter_cache/executors/utils.py", line 58, in single_nb_execution
    executenb(
  File "/opt/anaconda3/lib/python3.11/site-packages/nbclient/client.py", line 1314, in execute
    return NotebookClient(nb=nb, resources=resources, km=km, **kwargs).execute()
           ^^^^^^^^^^^^^^^^^^^^^^^^^^^^^^^^^^^^^^^^^^^^^^^^^^^^^^^^^^^^^^^^^^^^^
  File "/opt/anaconda3/lib/python3.11/site-packages/jupyter_core/utils/__init__.py", line 173, in wrapped
    return loop.run_until_complete(inner)
           ^^^^^^^^^^^^^^^^^^^^^^^^^^^^^^
  File "/opt/anaconda3/lib/python3.11/asyncio/base_events.py", line 653, in run_until_complete
    return future.result()
           ^^^^^^^^^^^^^^^
  File "/opt/anaconda3/lib/python3.11/site-packages/nbclient/client.py", line 709, in async_execute
    await self.async_execute_cell(
  File "/opt/anaconda3/lib/python3.11/site-packages/nbclient/client.py", line 1062, in async_execute_cell
    await self._check_raise_for_error(cell, cell_index, exec_reply)
  File "/opt/anaconda3/lib/python3.11/site-packages/nbclient/client.py", line 918, in _check_raise_for_error
    raise CellExecutionError.from_cell_and_msg(cell, exec_reply_content)
nbclient.exceptions.CellExecutionError: An error occurred while executing the following cell:
------------------
# import libaries
import numpy as np
import matplotlib.pyplot as plt
import matplotlib as mpl
mpl.rcParams['figure.dpi'] = 300
from scipy.signal import convolve2d as conv2
from skimage import color, data, restoration
from skimage.restoration import inpaint

# load test image and convert to gray-scale
astro = color.rgb2gray(data.astronaut())

## image deblurring

# define blurring kernel (pointspread function)
psf = np.ones((5, 5)) / 25

# convolve image with kernel
astro_blur = conv2(astro, psf, 'same')
astro_blur += (np.random.poisson(lam=25, size=astro.shape) - 10) / 255.

# Restore Image using Richardson-Lucy algorithm
astro_restored = restoration.richardson_lucy(astro_blur, psf, iterations=10)

# plot results
fig, ax = plt.subplots(nrows=1, ncols=3, figsize=(8, 5))
plt.gray()

for a in (ax[0], ax[1], ax[2]):
       a.axis('off')

ax[0].imshow(astro, vmin=0, vmax=1)
ax[0].set_title('Original image')

ax[1].imshow(astro_blur,vmin=0, vmax=1)
ax[1].set_title('Blurred image')

ax[2].imshow(astro_restored, vmin=0, vmax=1)
ax[2].set_title('Restored image')

plt.figtext(0,0.25,"An example of image deblurring. Do you think we would ever be able to fully recover the original image?",{"fontsize":12})
plt.show()
------------------


[0;31m---------------------------------------------------------------------------[0m
[0;31mTypeError[0m                                 Traceback (most recent call last)
Cell [0;32mIn[1], line 23[0m
[1;32m     20[0m astro_blur [38;5;241m+[39m[38;5;241m=[39m (np[38;5;241m.[39mrandom[38;5;241m.[39mpoisson(lam[38;5;241m=[39m[38;5;241m25[39m, size[38;5;241m=[39mastro[38;5;241m.[39mshape) [38;5;241m-[39m [38;5;241m10[39m) [38;5;241m/[39m [38;5;241m255.[39m
[1;32m     22[0m [38;5;66;03m# Restore Image using Richardson-Lucy algorithm[39;00m
[0;32m---> 23[0m astro_restored [38;5;241m=[39m restoration[38;5;241m.[39mrichardson_lucy(astro_blur, psf, iterations[38;5;241m=[39m[38;5;241m10[39m)
[1;32m     25[0m [38;5;66;03m# plot results[39;00m
[1;32m     26[0m fig, ax [38;5;241m=[39m plt[38;5;241m.[39msubplots(nrows[38;5;241m=[39m[38;5;241m1[39m, ncols[38;5;241m=[39m[38;5;241m3[39m, figsize[38;5;241m=[39m([38;5;241m8[39m, [38;5;241m5[39m))

[0;31mTypeError[0m: richardson_lucy() got an unexpected keyword argument 'iterations'

